2024-02-27 11:26:38,059 INFO    MainThread:63669 [wandb_setup.py:_flush():76] Current SDK version is 0.16.2
2024-02-27 11:26:38,059 INFO    MainThread:63669 [wandb_setup.py:_flush():76] Configure stats pid to 63669
2024-02-27 11:26:38,059 INFO    MainThread:63669 [wandb_setup.py:_flush():76] Loading settings from /home/dega/.config/wandb/settings
2024-02-27 11:26:38,059 INFO    MainThread:63669 [wandb_setup.py:_flush():76] Loading settings from /home/dega/projects/explainable_robotics_lm/wandb/settings
2024-02-27 11:26:38,059 INFO    MainThread:63669 [wandb_setup.py:_flush():76] Loading settings from environment variables: {}
2024-02-27 11:26:38,059 INFO    MainThread:63669 [wandb_setup.py:_flush():76] Inferring run settings from compute environment: {'program_relpath': 'model/llama2_peft_lora_inference.py', 'program_abspath': '/home/dega/projects/explainable_robotics_lm/model/llama2_peft_lora_inference.py', 'program': '/home/dega/projects/explainable_robotics_lm/model/llama2_peft_lora_inference.py'}
2024-02-27 11:26:38,059 INFO    MainThread:63669 [wandb_setup.py:_flush():76] Applying login settings: {'api_key': '***REDACTED***'}
2024-02-27 11:26:38,059 INFO    MainThread:63669 [wandb_setup.py:_flush():76] Applying login settings: {'api_key': '***REDACTED***'}
2024-02-27 11:26:38,059 INFO    MainThread:63669 [wandb_init.py:_log_setup():526] Logging user logs to /home/dega/projects/explainable_robotics_lm/wandb/run-20240227_112638-9heek0ev/logs/debug.log
2024-02-27 11:26:38,059 INFO    MainThread:63669 [wandb_init.py:_log_setup():527] Logging internal logs to /home/dega/projects/explainable_robotics_lm/wandb/run-20240227_112638-9heek0ev/logs/debug-internal.log
2024-02-27 11:26:38,059 INFO    MainThread:63669 [wandb_init.py:init():566] calling init triggers
2024-02-27 11:26:38,059 INFO    MainThread:63669 [wandb_init.py:init():573] wandb.init called with sweep_config: {}
config: {}
2024-02-27 11:26:38,059 INFO    MainThread:63669 [wandb_init.py:init():616] starting backend
2024-02-27 11:26:38,059 INFO    MainThread:63669 [wandb_init.py:init():620] setting up manager
2024-02-27 11:26:38,063 INFO    MainThread:63669 [backend.py:_multiprocessing_setup():105] multiprocessing start_methods=fork,spawn,forkserver, using: spawn
2024-02-27 11:26:38,064 INFO    MainThread:63669 [wandb_init.py:init():628] backend started and connected
2024-02-27 11:26:38,073 INFO    MainThread:63669 [wandb_init.py:init():720] updated telemetry
2024-02-27 11:26:38,073 INFO    MainThread:63669 [wandb_init.py:init():753] communicating run to backend with 90.0 second timeout
2024-02-27 11:26:38,464 ERROR   MainThread:63669 [wandb_init.py:init():779] encountered error: It appears that you do not have permission to access the requested resource. Please reach out to the project owner to grant you access. If you have the correct permissions, verify that there are no issues with your networking setup.(Error 404: Not Found)
2024-02-27 11:26:38,602 ERROR   MainThread:63669 [wandb_init.py:init():1194] It appears that you do not have permission to access the requested resource. Please reach out to the project owner to grant you access. If you have the correct permissions, verify that there are no issues with your networking setup.(Error 404: Not Found)
Traceback (most recent call last):
  File "/home/dega/miniconda3/envs/xar-language-model/lib/python3.9/site-packages/wandb/sdk/wandb_init.py", line 1176, in init
    run = wi.init()
  File "/home/dega/miniconda3/envs/xar-language-model/lib/python3.9/site-packages/wandb/sdk/wandb_init.py", line 785, in init
    raise error
wandb.errors.CommError: It appears that you do not have permission to access the requested resource. Please reach out to the project owner to grant you access. If you have the correct permissions, verify that there are no issues with your networking setup.(Error 404: Not Found)
2024-02-27 11:26:39,605 WARNING MsgRouterThr:63669 [router.py:message_loop():77] message_loop has been closed
